---
source: src/validation/tests/naming_validation_test.rs
assertion_line: 70
expression: res
---
SemanticError { message: "VLAs can not be defined as global variables", range: [SourceRange { range: 32..36 }], err_no: vla__invalid_container }
SyntaxError { message: "__ptr_to___arr_vla_2_int can not be used as a name because it is a built-in datatype", range: [SourceRange { range: 0..0 }], err_no: type__invalid_name }
SyntaxError { message: "__ptr_to___arr_vla_2_int can not be used as a name because it is a built-in datatype", range: [SourceRange { range: 0..0 }], err_no: type__invalid_name }
SyntaxError { message: "n_dims can not be used as a name because it is a built-in datatype", range: [SourceRange { range: 0..0 }, SourceRange { range: 0..0 }], err_no: type__invalid_name }
SyntaxError { message: "n_dims can not be used as a name because it is a built-in datatype", range: [SourceRange { range: 0..0 }, SourceRange { range: 0..0 }], err_no: type__invalid_name }
SyntaxError { message: "n_dims can not be used as a name because it is a built-in datatype", range: [SourceRange { range: 0..0 }, SourceRange { range: 0..0 }], err_no: type__invalid_name }

